Workbook

Sheet CONSOLIDADO 2026
A1: WEEK | B1: MXT/MXG | C1: ITEM | D1: SUPPLIER | E1: TYPE | F1: NO TOCAR | G1: REFERENCIA | H1: INVOICE # | I1: MOUTH | J1: INVOICE DATE | K1: PEDIMENTO | L1: PRO NUMBER/ TRACKING # | M1: IMPO/ EXPO MOOD | N1: TRAILER/ CONTAINER | O1: PAGO DE IMPUESTOS | P1: PAGO A TERCEROS | Q1: SUB-TOTAL | R1: IVA | S1: RETENTION | T1: TOTAL | U1: CURRENCY | V1: USD AMOUNT | W1: SHIP DATE | X1: SHIPPER | Y1: ORIGIN | Z1: DESTINATION | AA1: CONSIGNEE | AB1: BU | AC1: I/O | AD1: TYPE | AE1: ACCOUNT | AF1: COMMENTS | AG1: ACCOUNT | AH1: MXN AMOUNT | AI1: W | AJ1: CHARGE BACK | AK1: AMOUNT USD | AL1: INVOICED | AM1: PFA | AN1: PFA2 | AO1: PFA3
A2: 01 | B2: MXG | C2: 1 | D2: AERO WORLDWIDE GmbH | E2: Freight | F2: =E2&G2 -> FreightRM-A-0383AI25-M19 | G2: RM-A-0383AI25-M19 | H2: INV-1097 | I2: ENERO | J2: 46054 | L2: OTRO | M2: IMPO | N2: OTRO | O2: 0 | P2: 0 | Q2: 3121 | R2: 0 | S2: 0 | T2: 3121 | U2: USD | V2: =T2 -> 3121 | W2: VARIAS | X2: VARIOUS | Y2: VARIOUS | Z2: ZAC | AA2: JEG | AB2: M19 | AC2: I | AD2: AIR IMPO | AE2: 67130000 | AF2: NO COMMENTS | AI2: 01 | AJ2: NO | AK2: 0 | AL2: NO
A3: 01 | B3: MXG | C3: 2 | D3: DHL EXPRESS MEXICO, S.A. DE C.V. | E3: Freight | F3: =E3&G3 -> FreightPAQUETERIA | G3: PAQUETERIA | H3: ZCLIR00826898 | I3: ENERO | J3: 46054 | K3: OTRO | L3: 3636567771 | M3: AIR IMPO | N3: OTRO | O3: 0 | P3: 0 | Q3: 31467.62 | R3: 0 | S3: 0 | T3: 31467.62 | U3: MXN | V3: =T3/17.9075 -> 1757.2313 | W3: VARIAS | X3: JE_CHN | Y3: CHN | Z3: ZAC | AA3: JEG | AB3: M19 | AC3: I | AD3: AIR IMPO | AE3: 67130000 | AF3: NO COMMENTS | AI3: 01 | AJ3: NO | AK3: 0 | AL3: NO
A4: 01 | B4: MXG | C4: 3 | D4: DHL EXPRESS MEXICO, S.A. DE C.V. | E4: Freight | F4: =E4&G4 -> FreightRM-I-0970-AI25-M19 | G4: RM-I-0970-AI25-M19 | H4: ZCLIR00829111 | I4: ENERO | J4: 46266 | K4: OTRO | L4: VARIAS | M4: AIR IMPO | N4: OTRO | O4: 0 | P4: 0 | Q4: 35461.76 | R4: 1418.47 | S4: 0 | T4: 36880.23 | U4: MXN | V4: =T4/17.9075 -> 2059.4851 | W4: VARIAS | X4: VARIOUS | Y4: VARIOUS | Z4: ZAC | AA4: JEG | AB4: M19 | AC4: I | AD4: AIR IMPO | AE4: 67130000 | AF4: NO COMMENTS | AI4: 01 | AJ4: NO | AK4: 0 | AL4: NO
A5: 01 | B5: MXG | C5: 4 | D5: DHL EXPRESS MEXICO, S.A. DE C.V. | E5: Freight | F5: =E5&G5 -> FreightRM-I-0983-AI25-M19 | G5: RM-I-0983-AI25-M19 | H5: ZCLR006211093 | I5: ENERO | J5: 46054 | K5: OTRO | L5: 6201039272 | M5: AIR IMPO | N5: OTRO | O5: 0 | P5: 0 | Q5: 339.74 | R5: 54.36 | S5: 0 | T5: 394.1 | U5: MXN | V5: =T5/17.9075 -> 22.007539 | W5: VARIAS | X5: VARIOUS | Y5: VARIOUS | Z5: ZAC | AA5: JEG | AB5: M19 | AC5: I | AD5: AIR IMPO | AE5: 67130000 | AF5: NO COMMENTS | AI5: 01 | AJ5: NO | AK5: 0 | AL5: NO
A6: 01 | B6: MXG | C6: 5 | D6: DHL EXPRESS MEXICO, S.A. DE C.V. | E6: Freight | F6: =E6&G6 -> FreightFG-I-0422-AE26-M19 | G6: FG-I-0422-AE26-M19 | H6: ZCLR006221593 | I6: ENERO | J6: 46266 | K6: OTRO | L6: VARIAS | M6: AIR EXPO | N6: OTRO | O6: 0 | P6: 0 | Q6: 519.6 | R6: 83.14 | S6: 0 | T6: 602.74 | U6: MXN | V6: =T6/17.9075 -> 33.658523 | W6: VARIAS | X6: JEG | Y6: ZAC | Z6: VARIOUS | AA6: VARIOUS | AB6: M19 | AC6: O | AD6: AIR EXPO | AE6: 59230000 | AF6: NO COMMENTS | AI6: 01 | AJ6: NO | AK6: 0 | AL6: NO
A7: 01 | B7: MXG | C7: 6 | D7: DICEX S.A DE C.V. | E7: Broker | F7: =E7&G7 -> BrokerRM-M-195-SI25-M19-L-B | G7: RM-M-195-SI25-M19-L-B | H7: ALT81399 | I7: ENERO | J7: 46025 | K7: 25-810-3699-5005731 | L7: 721099314 | M7: IMPO | N7: TCKU7405737 | O7: 0 | P7: 3300.2 | Q7: 2553.99 | R7: 408.64 | S7: 0 | T7: 6262.83 | U7: MXN | V7: =T7/17.9075 -> 349.73224 | W7: 45989 | X7: SACO SHIPPING GMBH | Y7: GERMANY | Z7: MEX | AA7: INTERTEAM, S.A. DE C.V. | AB7: M19 | AC7: I | AD7: SEA IMPO | AE7: 67120000 | AF7: NO COMMENTS | AI7: 01 | AJ7: NO | AK7: 0 | AL7: NO
A8: 01 | B8: MXG | C8: 7 | D8: DICEX S.A DE C.V. | E8: Broker | F8: =E8&G8 -> BrokerRM-I-0934-AI24-M19 | G8: RM-I-0934-AI24-M19 | H8: GDL47609 | I8: ENERO | J8: 46013 | K8: 25-480-3993-5001694 | L8: 886495711575 | M8: AIR IMPO | N8: OTRO | O8: 0 | P8: 3991.85 | Q8: 806.86 | R8: 129.1 | S8: 0 | T8: 4927.81 | U8: MXN | V8: =T8/17.9075 -> 275.18135 | W8: 08-Dec-25 | X8: DICEX SA DE CV | Y8: USA | Z8: ZCL | AA8: JEG | AB8: M19 | AC8: I | AD8: AIR IMPO | AE8: 67130000 | AF8: NO COMMENTS | AI8: 01 | AJ8: NO | AK8: 0 | AL8: NO
A9: 01 | B9: MXG | C9: 8 | D9: DICEX S.A DE C.V. | E9: Broker | F9: =E9&G9 -> BrokerRM-I-0935-AI24-M19 | G9: RM-I-0935-AI24-M19 | H9: GDL47610 | I9: ENERO | J9: 46013 | K9: 25-480-3993-5001695 | L9: 886395798563 | M9: AIR IMPO | N9: OTRO | O9: 0 | P9: 2838.88 | Q9: 809.91 | R9: 129.59 | S9: 0 | T9: 3778.38 | U9: MXN | V9: =T9/17.9075 -> 210.99428 | W9: 03-Dec-25 | X9: DICEX SA DE CV | Y9: USA | Z9: ZCL | AA9: JEG | AB9: M19 | AC9: I | AD9: AIR IMPO | AE9: 67130000 | AF9: NO COMMENTS | AI9: 01 | AJ9: NO | AK9: 0 | AL9: NO
A10: 01 | B10: MXG | C10: 9 | D10: DICEX S.A DE C.V. | E10: Broker | F10: =E10&G10 -> BrokerRM-I-0940-AI24-M19 | G10: RM-I-0940-AI24-M19 | H10: GDL47611 | I10: ENERO | J10: 46013 | K10: 25-480-3993-5001696 | L10: 886778414045 | M10: AIR IMPO | N10: OTRO | O10: 0 | P10: 2763.96 | Q10: 804.86 | R10: 128.78 | S10: 0 | T10: 3697.6 | U10: MXN | V10: =T10/17.9075 -> 206.48332 | W10: 03-Dec-25 | X10: DICEX SA DE CV | Y10: USA | Z10: ZCL | AA10: JEG | AB10: M19 | AC10: I | AD10: AIR IMPO | AE10: 67130000 | AF10: NO COMMENTS | AI10: 01 | AJ10: NO | AK10: 0 | AL10: NO
A11: 01 | B11: MXG | C11: 10 | D11: DICEX S.A DE C.V. | E11: Broker | F11: =E11&G11 -> BrokerRM-I-0945-AI24-M19 | G11: RM-I-0945-AI24-M19 | H11: GDL47612 | I11: ENERO | J11: 46013 | K11: 25-480-3993-5001710 | L11: 886848925377 | M11: AIR IMPO | N11: OTRO | O11: 0 | P11: 2759.73 | Q11: 803 | R11: 128.48 | S11: 0 | T11: 3691.21 | U11: MXN | V11: =T11/17.9075 -> 206.12648 | W11: 03-Dec-25 | X11: DICEX SA DE CV | Y11: USA | Z11: ZCL | AA11: JEG | AB11: M19 | AC11: I | AD11: AIR IMPO | AE11: 67130000 | AF11: NO COMMENTS | AI11: 01 | AJ11: NO | AK11: 0 | AL11: NO
A12: 01 | B12: MXG | C12: 11 | D12: DICEX S.A DE C.V. | E12: Broker | F12: =E12&G12 -> BrokerRM-I-0946-AI24-M19 | G12: RM-I-0946-AI24-M19 | H12: GDL47613 | I12: ENERO | J12: 46013 | K12: 25-480-3993-5001711 | L12: 886695033050 | M12: AIR IMPO | N12: OTRO | O12: 0 | P12: 2759.73 | Q12: 805.18 | R12: 128.83 | S12: 0 | T12: 3693.74 | U12: MXN | V12: =T12/17.9075 -> 206.26776 | W12: 04-Dec-25 | X12: DICEX SA DE CV | Y12: CHN | Z12: ZCL | AA12: JEG | AB12: M19 | AC12: I | AD12: AIR IMPO | AE12: 67130000 | AF12: NO COMMENTS | AI12: 01 | AJ12: NO | AK12: 0 | AL12: NO
A13: 01 | B13: MXG | C13: 12 | D13: DICEX S.A DE C.V. | E13: Broker | F13: =E13&G13 -> BrokerRM-I-0947-AI24-M19 | G13: RM-I-0947-AI24-M19 | H13: GDL47614 | I13: ENERO | J13: 46013 | K13: 25-480-3993-5001712 | L13: 886647776083 | M13: AIR IMPO | N13: OTRO | O13: 0 | P13: 2759.73 | Q13: 805.18 | R13: 128.83 | S13: 0 | T13: 3693.74 | U13: MXN | V13: =T13/17.9075 -> 206.26776 | W13: 05-Dec-25 | X13: DICEX SA DE CV | Y13: USA | Z13: ZCL | AA13: JEG | AB13: M19 | AC13: I | AD13: AIR IMPO | AE13: 67130000 | AF13: NO COMMENTS | AI13: 01 | AJ13: NO | AK13: 0 | AL13: NO
A14: 01 | B14: MXG | C14: 13 | D14: DICEX S.A DE C.V. | E14: Broker | F14: =E14&G14 -> BrokerRM-I-0953-AI24-M19 | G14: RM-I-0953-AI24-M19 | H14: GDL47615 | I14: ENERO | J14: 46013 | K14: 25-480-3993-5001717 | L14: 886937395946 | M14: AIR IMPO | N14: OTRO | O14: 0 | P14: 3181.38 | Q14: 803.34 | R14: 128.53 | S14: 0 | T14: 4113.25 | U14: MXN | V14: =T14/17.9075 -> 229.69426 | W14: 10-Dec-25 | X14: DICEX SA DE CV | Y14: CHN | Z14: ZCL | AA14: JEG | AB14: M19 | AC14: I | AD14: AIR IMPO | AE14: 67130000 | AF14: NO COMMENTS | AI14: 01 | AJ14: NO | AK14: 0 | AL14: NO
A15: 01 | B15: MXG | C15: 14 | D15: DICEX S.A DE C.V. | E15: Broker | F15: =E15&G15 -> BrokerRM-I-0952-AI24-M19 | G15: RM-I-0952-AI24-M19 | H15: GDL47616 | I15: ENERO | J15: 46013 | K15: 25-480-3993-5001718 | L15: 886630817791 | M15: AIR IMPO | N15: OTRO | O15: 0 | P15: 3181.38 | Q15: 805.18 | R15: 128.83 | S15: 0 | T15: 4115.39 | U15: MXN | V15: =T15/17.9075 -> 229.81377 | W15: 10-Dec-25 | X15: DICEX SA DE CV | Y15: CHN | Z15: ZCL | AA15: JEG | AB15: M19 | AC15: I | AD15: AIR IMPO | AE15: 67130000 | AF15: NO COMMENTS | AI15: 01 | AJ15: NO | AK15: 0 | AL15: NO
A16: 01 | B16: MXG | C16: 15 | D16: DICEX S.A DE C.V. | E16: Broker | F16: =E16&G16 -> BrokerRM-I-0960-AI24-M19 | G16: RM-I-0960-AI24-M19 | H16: GDL47617 | I16: ENERO | J16: 46013 | K16: 25-480-3993-5001730 | L16: 886972205991 | M16: AIR IMPO | N16: OTRO | O16: 0 | P16: 3892.34 | Q16: 803.97 | R16: 128.64 | S16: 0 | T16: 4824.95 | U16: MXN | V16: =T16/17.9075 -> 269.43739 | W16: 10-Dec-25 | X16: DICEX SA DE CV | Y16: CHN | Z16: ZCL | AA16: JEG | AB16: M19 | AC16: I | AD16: AIR IMPO | AE16: 67130000 | AF16: NO COMMENTS | AI16: 01 | AJ16: NO | AK16: 0 | AL16: NO
A17: 01 | B17: MXG | C17: 16 | D17: DICEX S.A DE C.V. | E17: Broker | F17: =E17&G17 -> BrokerRM-I-0961-AI24-M19 | G17: RM-I-0961-AI24-M19 | H17: GDL47618 | I17: ENERO | J17: 46013 | K17: 25-480-3993-5001731 | L17: 887018804665 | M17: AIR IMPO | N17: OTRO | O17: 0 | P17: 3892.34 | Q17: 803.97 | R17: 128.64 | S17: 0 | T17: 4824.95 | U17: MXN | V17: =T17/17.9075 -> 269.43739 | W17: 10-Dec-25 | X17: DICEX SA DE CV | Y17: CHN | Z17: ZCL | AA17: JEG | AB17: M19 | AC17: I | AD17: AIR IMPO | AE17: 67130000 | AF17: NO COMMENTS | AI17: 01 | AJ17: NO | AK17: 0 | AL17: NO
A18: 01 | B18: MXG | C18: 17 | D18: DICEX S.A DE C.V. | E18: Broker | F18: =E18&G18 -> BrokerRM-I-0962-AI24-M19 | G18: RM-I-0962-AI24-M19 | H18: GDL47619 | I18: ENERO | J18: 46013 | K18: 25-480-3993-5001732 | L18: 887092934199 | M18: AIR IMPO | N18: OTRO | O18: 0 | P18: 2742.99 | Q18: 797.33 | R18: 127.57 | S18: 0 | T18: 3667.89 | U18: MXN | V18: =T18/17.9075 -> 204.82424 | W18: 10-Dec-25 | X18: DICEX SA DE CV | Y18: CHN | Z18: ZCL | AA18: JEG | AB18: M19 | AC18: I | AD18: AIR IMPO | AE18: 67130000 | AF18: NO COMMENTS | AI18: 01 | AJ18: NO | AK18: 0 | AL18: NO
A19: 01 | B19: MXG | C19: 18 | D19: DICEX S.A DE C.V. | E19: Broker | F19: =E19&G19 -> BrokerFG-A-0382AI25-M19-C8714.D | G19: FG-A-0382AI25-M19-C8714.D | H19: MEX124375 | I19: ENERO | J19: 46014 | K19: 25-85-34165018080 | L19: 2025/11/24-01 | M19: AIR IMPO | N19: OTRO | O19: 0 | P19: 33385.87 | Q19: 1893.24 | R19: 302.92 | S19: 0 | T19: 35582.03 | U19: MXN | V19: =T19/17.9075 -> 1986.9904 | W19: 46014 | X19: JOHNSON ELECTRIC INDUSTRIAL MANUFACTORY LIMITED | Y19: USA | Z19: ZAC | AA19: JEG | AB19: M19 | AC19: I | AD19: AIR IMPO | AE19: 67180000 | AF19: NO COMMENTS | AI19: 01 | AJ19: NO | AK19: 0 | AL19: NO | AM19: CS000008714
A20: 01 | B20: MXG | C20: 19 | D20: DICEX S.A DE C.V. | E20: Broker | F20: =E20&G20 -> BrokerRM-M-466-SI25-M19-B | G20: RM-M-466-SI25-M19-B | H20: MZO185520 | I20: ENERO | J20: 46003 | K20: 25 16 1690 5038712 | L20: OOLU2038118971 | M20: IMPO | N20: TLLU7511375 | O20: 0 | P20: 7134 | Q20: 0 | R20: 0 | S20: 0 | T20: 7134 | U20: MXN | V20: =T20/17.9075 -> 398.38057 | W20: 12-Dec-25 | X20: JOHNSON ELECTRIC INDUSTRIAL MANUFACTORY LIMITED | Y20: CHN | Z20: ZCL | AA20: JEG | AB20: M19 | AC20: I | AD20: SEA IMPO | AE20: 67120000 | AF20: COMPLEMENTARIA DE LA CUENTA MZO185283 | AI20: 01 | AJ20: NO | AK20: 0 | AL20: NO
A21: 01 | B21: MXG | C21: 20 | D21: DICEX S.A DE C.V. | E21: Broker | F21: =E21&G21 -> BrokerRM-M-487-SI25-M19-B | G21: RM-M-487-SI25-M19-B | H21: MZO185524 | I21: ENERO | J21: 46003 | K21: 25 16 1690 5042158 | L21: COSU6433823132 | M21: IMPO | N21: OOLU9447086 | O21: 0 | P21: 11671.42 | Q21: 3631.63 | R21: 581.07 | S21: 0 | T21: 15884.12 | U21: MXN | V21: =T21/17.9075 -> 887.00935 | W21: 12-Dec-25 | X21: JOHNSON ELECTRIC INDUSTRIAL MANUFACTORY LIMITED | Y21: CHN | Z21: ZCL | AA21: JEG | AB21: M19 | AC21: I | AD21: SEA IMPO | AE21: 67120000 | AF21: NO COMMENTS | AI21: 01 | AJ21: NO | AK21: 0 | AL21: NO
A22: 01 | B22: MXG | C22: 21 | D22: DICEX S.A DE C.V. | E22: Broker | F22: =E22&G22 -> BrokerRM-M-485-SI25-M19-B | G22: RM-M-485-SI25-M19-B | H22: MZO185525 | I22: ENERO | J22: 46003 | K22: 25 16 1690 5042160 | L22: COSU6433823130 | M22: IMPO | N22: TRHU4721473 | O22: 0 | P22: 14542.42 | Q22: 5014.41 | R22: 802.31 | S22: 0 | T22: 20359.14 | U22: MXN | V22: =T22/17.9075 -> 1136.9058 | W22: 12-Dec-25 | X22: JOHNSON ELECTRIC INDUSTRIAL MANUFACTORY LIMITED | Y22: CHN | Z22: ZCL | AA22: JEG | AB22: M19 | AC22: I | AD22: SEA IMPO | AE22: 67120000 | AF22: NO COMMENTS | AI22: 01 | AJ22: NO | AK22: 0 | AL22: NO
A23: 01 | B23: MXG | C23: 22 | D23: DICEX S.A DE C.V. | E23: Broker | F23: =E23&G23 -> BrokerRM-M-489-SI25-M19-B | G23: RM-M-489-SI25-M19-B | H23: MZO185526 | I23: ENERO | J23: 46003 | K23: 25 16 1690 5042102 | L23: MEDURH066769 | M23: IMPO | N23: TCNU2464881 | O23: 0 | P23: 13874.37 | Q23: 6110.48 | R23: 977.68 | S23: 0 | T23: 20962.53 | U23: MXN | V23: =T23/17.9075 -> 1170.6006 | W23: 12-Dec-25 | X23: OHNSON ELECTRIC INDUSTRIAL MANUFACTORY LIMITED | Y23: CHN | Z23: ZCL | AA23: JEG | AB23: M19 | AC23: I | AD23: SEA IMPO | AE23: 67120000 | AF23: NO COMMENTS | AI23: 01 | AJ23: NO | AK23: 0 | AL23: NO
A24: 01 | B24: MXG | C24: 23 | D24: DICEX S.A DE C.V. | E24: Broker | F24: =E24&G24 -> BrokerRM-M-479-SI25-M19-B | G24: RM-M-479-SI25-M19-B | H24: MZO185532 | I24: ENERO | J24: 46003 | K24: 25 16 1690 5038784 | L24: OOLU2038131940 | M24: IMPO | N24: OOCU7349926 | O24: 0 | P24: 23759.85 | Q24: 3169.12 | R24: 507.05 | S24: 0 | T24: 27436.02 | U24: MXN | V24: =T24/17.9075 -> 1532.0966 | W24: 12-Dec-25 | X24: OHNSON ELECTRIC INDUSTRIAL MANUFACTORY LIMITED | Y24: CHN | Z24: ZCL | AA24: JEG | AB24: M19 | AC24: I | AD24: SEA IMPO | AE24: 67120000 | AF24: NO COMMENTS | AI24: 01 | AJ24: NO | AK24: 0 | AL24: NO
A25: 01 | B25: MXG | C25: 24 | D25: DICEX S.A DE C.V. | E25: Broker | F25: =E25&G25 -> BrokerRM-M-480-SI25-M19-B | G25: RM-M-480-SI25-M19-B | H25: MZO185533 | I25: ENERO | J25: 46003 | K25: 25 16 1690 5038783 | L25: OOLU2038131941 | M25: IMPO | N25: OOCU7818659 | O25: 0 | P25: 23165.93 | Q25: 3664.47 | R25: 586.31 | S25: 0 | T25: 27416.71 | U25: MXN | V25: =T25/17.9075 -> 1531.0183 | W25: 12-Dec-25 | X25: JOHNSON ELECTRIC INDUSTRIAL MANUFACTORY LIMITED | Y25: CHN | Z25: ZCL | AA25: JEG | AB25: M19 | AC25: I | AD25: SEA IMPO | AE25: 67120000 | AF25: NO COMMENTS | AI25: 01 | AJ25: NO | AK25: 0 | AL25: NO
A26: 01 | B26: MXG | C26: 25 | D26: DICEX S.A DE C.V. | E26: Broker | F26: =E26&G26 -> BrokerRM-M-492-SI25-M19-B | G26: RM-M-492-SI25-M19-B | H26: MZO185614 | I26: ENERO | J26: 46003 | K26: 25 16 1690 5038773 | L26: OOLU2038157981 | M26: IMPO | N26: TGBU7698706 | O26: 0 | P26: 15672.47 | Q26: 3544.16 | R26: 567.06 | S26: 0 | T26: 19783.69 | U26: MXN | V26: =T26/17.9075 -> 1104.7712 | W26: 12-Dec-25 | X26: JOHNSON ELECTRIC INDUSTRIAL MANUFACTORY LIMITED | Y26: CHN | Z26: ZCL | AA26: JEG | AB26: M19 | AC26: I | AD26: SEA IMPO | AE26: 67120000 | AF26: NO COMMENTS | AI26: 01 | AJ26: NO | AK26: 0 | AL26: NO
A27: 01 | B27: MXG | C27: 26 | D27: DICEX S.A DE C.V. | E27: Broker | F27: =E27&G27 -> BrokerRM-M-491-SI25-M19-B | G27: RM-M-491-SI25-M19-B | H27: MZO185619 | I27: ENERO | J27: 46003 | K27: 25 16 1690 5038774 | L27: OOLU2038157980 | M27: IMPO | N27: OOCU8377500 | O27: 0 | P27: 15375.51 | Q27: 3248.84 | R27: 519.81 | S27: 0 | T27: 19144.16 | U27: MXN | V27: =T27/17.9075 -> 1069.0582 | W27: 12-Dec-25 | X27: JOHNSON ELECTRIC INDUSTRIAL MANUFACTORY LIMITE | Y27: CHN | Z27: ZCL | AA27: JEG | AB27: M19 | AC27: I | AD27: SEA IMPO | AE27: 67120000 | AF27: NO COMMENTS | AI27: 01 | AJ27: NO | AK27: 0 | AL27: NO
A28: 01 | B28: MXG | C28: 27 | D28: DICEX S.A DE C.V. | E28: Broker | F28: =E28&G28 -> BrokerRM-M-478-SI25-M19-B | G28: RM-M-478-SI25-M19-B | H28: MZO185626 | I28: ENERO | J28: 46003 | K28: 25 16 1690 5038780 | L28: OOLU2038131950 | M28: IMPO | N28: FBIU5272988 | O28: 0 | P28: 33390.57 | Q28: 5128.66 | R28: 820.58 | S28: 0 | T28: 39339.81 | U28: MXN | V28: =T28/17.9075 -> 2196.8343 | W28: 12-Dec-25 | X28: JOHNSON ELECTRIC INDUSTRIAL MANUFACTORY LIMITE | Y28: CHN | Z28: ZCL | AA28: JEG | AB28: M19 | AC28: I | AD28: SEA IMPO | AE28: 67120000 | AF28: NO COMMENTS | AI28: 01 | AJ28: NO | AK28: 0 | AL28: NO
A29: 01 | B29: MXG | C29: 28 | D29: DICEX S.A DE C.V. | E29: Broker | F29: =E29&G29 -> BrokerRM-M-488-SI25-M19-B | G29: RM-M-488-SI25-M19-B | H29: MZO185640 | I29: ENERO | J29: 46003 | K29: 25 16 1690 5042157 | L29: COSU6433823133 | M29: IMPO | N29: CSNU7797874 | O29: 0 | P29: 11671.42 | Q29: 6693.5 | R29: 1070.96 | S29: 0 | T29: 19435.88 | U29: MXN | V29: =T29/17.9075 -> 1085.3486 | W29: 12-Dec-25 | X29: JOHNSON ELECTRIC INDUSTRIAL MANUFACTORY LIMITED | Y29: CHN | Z29: ZCL | AA29: JEG | AB29: M19 | AC29: I | AD29: SEA IMPO | AE29: 67120000 | AF29: NO COMMENTS | AI29: 01 | AJ29: NO | AK29: 0 | AL29: NO
A30: 01 | B30: MXG | C30: 29 | D30: DICEX S.A DE C.V. | E30: Broker | F30: =E30&G30 -> BrokerRM-M-490-SI25-M19-B | G30: RM-M-490-SI25-M19-B | H30: MZO185644 | I30: ENERO | J30: 46003 | K30: 25 16 1690 5042156 | L30: OOLU2038174630 | M30: IMPO | N30: CSNU6882837 | O30: 0 | P30: 12430.27 | Q30: 4920.08 | R30: 787.21 | S30: 0 | T30: 18137.56 | U30: MXN | V30: =T30/17.9075 -> 1012.8471 | W30: 12-Dec-25 | X30: JOHNSON ELECTRIC INDUSTRIAL MANUFACTORY LIMITED | Y30: CHN | Z30: ZCL | AA30: JEG | AB30: M19 | AC30: I | AD30: SEA IMPO | AE30: 67120000 | AF30: NO COMMENTS | AI30: 01 | AJ30: NO | AK30: 0 | AL30: NO
A31: 01 | B31: MXG | C31: 30 | D31: DICEX S.A DE C.V. | E31: Broker | F31: =E31&G31 -> BrokerRM-M-488-SI25-M19-B | G31: RM-M-488-SI25-M19-B | H31: MZO185726 | I31: ENERO | J31: 46006 | K31: 25 16 1690 5042161 | L31: COSU6433823133 | M31: IMPO | N31: CSNU7797874 | O31: 0 | P31: 0 | Q31: 1498.91 | R31: 239.83 | S31: 0 | T31: 1738.74 | U31: MXN | V31: =T31/17.9075 -> 97.09563 | W31: 15-Dec-25 | X31: JOHNSON ELECTRIC INDUSTRIAL MANUFACTORY LIMITED | Y31: CHN | Z31: ZCL | AA31: JEG | AB31: M19 | AC31: I | AD31: SEA IMPO | AE31: 67120000 | AF31: NO COMMENTS | AI31: 01 | AJ31: NO | AK31: 0 | AL31: NO
... A52: 01 | B52: MXG | C52: 51 | D52: DICEX S.A DE C.V. | E52: Broker | F52: =E52&G52 -> BrokerRM-M-511-SI25-M19-B | G52: RM-M-511-SI25-M19-B | H52: MZO186262 | I52: ENERO | J52: 46010 | K52: 25 16 1690 5042748 | L52: COSU6435196943 | M52: IMPO | N52: SEGU6880793 | O52: 0 | P52: 11657.02 | Q52: 6368.64 | R52: 1018.98 | S52: 0 | T52: 19044.64 | U52: MXN | V52: =T52/17.9075 -> 1063.5008 | W52: 19-Dec-25 | X52: JOHNSON ELECTRIC INDUSTRIAL MANUFACTORY LIMITED | Y52: CHN | Z52: ZCL | AA52: JEG | AB52: M19 | AC52: I | AD52: SEA IMPO | AE52: 67120000 | AF52: NO COMMENTS | AI52: 01 | AJ52: NO | AK52: 0 | AL52: NO
A53: 01 | B53: MXG | C53: 52 | D53: DICEX S.A DE C.V. | E53: Broker | F53: =E53&G53 -> BrokerRM-M-208-SI25-M19-L-B | G53: RM-M-208-SI25-M19-L-B | H53: MZO186743 | I53: ENERO | J53: 46024 | K53: 25 16 1690 5043460 | L53: COSU6435332521 | M53: IMPO | N53: COSU6435332521 | O53: 0 | P53: 9066.56 | Q53: 2632.1 | R53: 421.13 | S53: 0 | T53: 12119.79 | U53: MXN | V53: =T53/17.9075 -> 676.79966 | W53: 46024 | X53: HONGKONG LIPIN INT'L LIMITED | Y53: CHN | Z53: ZCL | AA53: JEG | AB53: M19 | AC53: I | AD53: SEA IMPO | AE53: 67120000 | AF53: NO COMMENTS | AI53: 01 | AJ53: NO | AK53: 0 | AL53: NO
A54: 01 | B54: MXG | C54: 53 | D54: DICEX S.A DE C.V. | E54: Broker | F54: =E54&G54 -> BrokerRM-M-192-SI25-M19-L-B | G54: RM-M-192-SI25-M19-L-B | H54: MZO186744 | I54: ENERO | J54: 46024 | K54: 25 16 1690 5042735 | L54: HLCUSEL251127440 | M54: IMPO | N54: HLCUSEL251127440 | O54: 0 | P54: 9101.54 | Q54: 2728.27 | R54: 436.52 | S54: 0 | T54: 12266.33 | U54: MXN | V54: =T54/17.9075 -> 684.98283 | W54: 46024 | X54: JOHNSON ELECTRIC PVT LTD | Y54: CHN | Z54: ZCL | AA54: JEG | AB54: M19 | AC54: I | AD54: SEA IMPO | AE54: 67120000 | AF54: NO COMMENTS | AI54: 01 | AJ54: NO | AK54: 0 | AL54: NO
A55: 01 | B55: MXG | C55: 54 | D55: DICEX S.A DE C.V. | E55: Broker | F55: =E55&G55 -> BrokerRM-M-201-SI25-M19-L-B | G55: RM-M-201-SI25-M19-L-B | H55: MZO186746 | I55: ENERO | J55: 46024 | K55: 25 16 1690 5043457 | L55: HLCUSEL251156604 | M55: IMPO | N55: HLCUSEL251156604 | O55: 0 | P55: 7674.56 | Q55: 2696.31 | R55: 431.41 | S55: 0 | T55: 10802.28 | U55: MXN | V55: =T55/17.9075 -> 603.22658 | W55: 46024 | X55: ELNA AMERICA, INC | Y55: CHN | Z55: ZCL | AA55: JEG | AB55: M19 | AC55: I | AD55: SEA IMPO | AE55: 67120000 | AF55: NO COMMENTS | AI55: 01 | AJ55: NO | AK55: 0 | AL55: NO
A56: 01 | B56: MXG | C56: 55 | D56: DICEX S.A DE C.V. | E56: Broker | F56: =E56&G56 -> BrokerRM-M-214-SI25-M19-L-B | G56: RM-M-214-SI25-M19-L-B | H56: MZO186748 | I56: ENERO | J56: 46024 | K56: 25 16 1690 5042751 | L56: 264868494 | M56: IMPO | N56: 264868494 | O56: 0 | P56: 8891.4 | Q56: 2605.07 | R56: 416.81 | S56: 0 | T56: 11913.28 | U56: MXN | V56: =T56/17.9075 -> 665.26763 | W56: 46024 | X56: SHANGHAI KRAH ELECTRONICS CO; LTD | Y56: CHN | Z56: ZCL | AA56: JEG | AB56: M19 | AC56: I | AD56: SEA IMPO | AE56: 67120000 | AF56: NO COMMENTS | AI56: 01 | AJ56: NO | AK56: 0 | AL56: NO
A57: 01 | B57: MXG | C57: 56 | D57: DICEX S.A DE C.V. | E57: Broker | F57: =E57&G57 -> BrokerRM-M-204-SI25-M19-L-B | G57: RM-M-204-SI25-M19-L-B | H57: MZO186749 | I57: ENERO | J57: 46024 | K57: 25 16 1690 5043456 | L57: HLCUSEL251156604 | M57: IMPO | N57: HLCUSEL251156604 | O57: 0 | P57: 7674.56 | Q57: 2599.22 | R57: 415.87 | S57: 0 | T57: 10689.65 | U57: MXN | V57: =T57/17.9075 -> 596.93704 | W57: 46024 | X57: ELNA AMERICA, INC | Y57: CHN | Z57: ZCL | AA57: JEG | AB57: M19 | AC57: I | AD57: SEA IMPO | AE57: 67120000 | AF57: NO COMMENTS | AI57: 01 | AJ57: NO | AK57: 0 | AL57: NO
A58: 01 | B58: MXG | C58: 57 | D58: DICEX S.A DE C.V. | E58: Broker | F58: =E58&G58 -> BrokerRM-M-189-SI25-M19-L-B | G58: RM-M-189-SI25-M19-L-B | H58: MZO186920 | I58: ENERO | J58: 46024 | K58: 25 16 1690 5042734 | L58: HLCUSEL251017563 | M58: IMPO | N58: HLCUSEL251017563 | O58: 0 | P58: 9101.54 | Q58: 2531.77 | R58: 405.08 | S58: 0 | T58: 12038.39 | U58: MXN | V58: =T58/17.9075 -> 672.25408 | W58: 46024 | X58: JOHNSON ELECTRIC PVT LTD | Y58: CHN | Z58: ZCL | AA58: JEG | AB58: M19 | AC58: I | AD58: SEA IMPO | AE58: 67120000 | AF58: NO COMMENTS | AI58: 01 | AJ58: NO | AK58: 0 | AL58: NO
A59: 01 | B59: MXG | C59: 58 | D59: DICEX S.A DE C.V. | E59: Broker | F59: =E59&G59 -> BrokerRM-M-483-SI25-M19-B | G59: RM-M-483-SI25-M19-B | H59: MZO186996 | I59: ENERO | J59: 46024 | K59: 25 16 1690 5038775 | L59: MEDUKH433089 | M59: EXPO | N59: BMOU6550304 | O59: 0 | P59: 0 | Q59: 1990 | R59: 318.4 | S59: 0 | T59: 2308.4 | U59: MXN | V59: =T59/17.9075 -> 128.90688 | W59: 46024 | X59: JOHNSON ELECTRIC INDUSTRIAL MANUFACTORY LIMITED | Y59: CHN | Z59: ZCL | AA59: JEG | AB59: M19 | AC59: I | AD59: SEA IMPO | AE59: 67120000 | AF59: COMPLEMENTARIA DE LA CUENTA MZO184599 | AI59: 01 | AJ59: NO | AK59: 0 | AL59: NO
A60: 01 | B60: MXG | C60: 59 | D60: DICEX S.A DE C.V. | E60: Broker | F60: =E60&G60 -> BrokerRM-M-523-SI25-M19-B | G60: RM-M-523-SI25-M19-B | H60: MZO187006 | I60: ENERO | J60: 46024 | K60: 25 16 1690 5043760 | L60: OOLU2038223200 | M60: IMPO | N60: CSNU6814540 | O60: 0 | P60: 0 | Q60: 2438.4 | R60: 390.14 | S60: 0 | T60: 2828.54 | U60: MXN | V60: =T60/17.9075 -> 157.95281 | W60: 46024 | X60: JOHNSON ELECTRIC INDUSTRIAL MANUFACTORY LIMITE | Y60: CHN | Z60: ZCL | AA60: JEG | AB60: M19 | AC60: I | AD60: SEA IMPO | AE60: 67120000 | AF60: NO COMMENTS | AI60: 01 | AJ60: NO | AK60: 0 | AL60: NO
...

Sheet HT
A1: FG-R-2069LR25.M19 | B1: NL239198 | O1: FECHA FACTURA | P1: FOLIO FACTURA | Q1: TRANSPORT ORDER | R1: FECHA VENCIMIENTO | S1: MONEDA | T1: DIAS DE VENCIMIENTO | U1: IMPORTE | V1: ESTATUS FACT | W1: REFERENCIA
A2: FG-R-2068LR25.M19 | B2: NL239198 | O2: 45811 | P2: 542336 | Q2: XPD/MX/AI/24120046775 | R2: 20/04/2025 | S2: USD | T2: 274 | U2: $ 1,405.60 | V2: VENCIDA | W2: RM-A-0169AI24-M19 | X2: 1405.6 | Y2: 1340
A3: FG-R-2067LR25.M01 | B3: NL239198 | O3: 45811 | P3: 542489 | Q3: LOD1300354 | R3: 20/04/2025 | S3: USD | T3: 274 | U3: $ 575.00 | V3: VENCIDA | W3: RM-R-0239LI24-M19 | X3: 575
A4: FG-R-2075LE25.M01 | B4: NL239399 | O4: 45811 | P4: 542492 | Q4: LOD1333794 | R4: 20/04/2025 | S4: USD | T4: 274 | U4: $ 320.00 | V4: VENCIDA | W4: RM-J-0065LI24-M19 | X4: 320 | Y4: N/E
A5: FG-R-2076LE25.M19 | B5: NL239399 | O5: 45964 | P5: 543444 | Q5: XPD/MX/RI/24120046891 | R5: 25/04/2025 | S5: USD | T5: 269 | U5: $ 924.00 | V5: VENCIDA | W5: RM-J-0275LI24-M19 | X5: 924 | Y5: N/E
A6: FG-R-2078LE25.M19 | B6: NL239399 | O6: 24/03/2025 | P6: 546784 | Q6: EP/AGU/SI/S/2024/013921 | R6: 45874 | S6: USD | T6: 256 | U6: $ 907.20 | V6: VENCIDA | W6: RM-M-017-SI24-M19-L SUSTITUTYE 521607 | X6: 907.2 | Y6: E/D EUR/XPD
A7: RM-A-0003AI26-M19-C9038.D | B7: MEX125301 | O7: 28/03/2025 | P7: 548215 | Q7: XPD/MX/SI/24110030461 | R7: 45996 | S7: USD | T7: 252 | U7: $ 2,701.60 | V7: VENCIDA | W7: RM-M-135-SI24-M19-L | X7: 2701.6 | Y7: DSV
A8: RM-A-0011AI26-M19.PFA.D | B8: MEX125301 | O8: 28/03/2025 | P8: 548218 | Q8: XPD/MX/SI/24090016489 | R8: 45996 | S8: USD | T8: 252 | U8: $ 1,468.40 | V8: VENCIDA | W8: RM-M-111-SI24-M19-L | X8: 1468.4 | Y8: DSV
A9: RM-A-0012AI26-M19.PFA.D | B9: MEX125301 | O9: 31/03/2025 | P9: 548526 | Q9: XPD/MX/SI/24110029932 | R9: 15/05/2025 | S9: USD | T9: 249 | U9: $ 1,168.80 | V9: VENCIDA | W9: RM-M-137-SI24-M19-L | X9: 1168.8 | Y9: E
A10: FG-R-2077LE25.M19 | B10: NL240119 | X10: =SUM(X2:X9) -> 9470.6
A11: FG-R-2084LE25.M19 | B11: NL240119
A12: FG-R-2087LE25.M19 | B12: NL240126
A13: FG-R-2086LE25.M19 | B13: NL240126 | F13: 67110002 | G13: LAND IMPO | H13: 67110002
A14: RM-M-540-SI25-M19 | B14: CAL-3958 | F14: 67115005 | G14: STORAGE | H14: 67115005
A15: RM-M-541-SI25-M19 | B15: CAL-3958 | F15: 67120000 | G15: SEA IMPO | H15: 67120000 | I15: 67110003
A16: RM-M-516-SI25-M19 | B16: CAL-3959 | F16: 67130000 | G16: AIR IMPO | H16: 67130000
A17: RM-M-525-SI25-M19 | B17: CAL-3959 | F17: 67155001 | G17: DUTY | H17: 67155001
A18: RM-M-535-SI25-M19 | B18: CAL-3961 | F18: 67170000 | G18: DUTY | H18: 67170000
A19: RM-M-538-SI25-M19 | B19: CAL-3961 | F19: 67180000 | G19: PREMIUM | H19: 67180000
A20: RM-M-532-SI25-M19 | B20: CAL-3975 | F20: 59210003 | G20: LAND EXPO | H20: 59210003
A21: RM-M-533-SI25-M19 | B21: CAL-3975 | F21: 59220000 | G21: SEA EXPO | H21: 59220000
A22: AF-M-493-SI25-M23 | B22: CAL-3960 | F22: 59230000 | G22: AIR EXPO | H22: 59230000
A23: AF-M-496-SI25-M23 | B23: CAL-3960 | F23: 59234005 | G23: PREMIUM | H23: 59234005
A24: RM-M-491-SI25-M19 | B24: CAL-3970 | F24: 59210002 | G24: LAND EXPO | H24: 59210002
A25: RM-M-492-SI25-M19 | B25: CAL-3970
A26: RM-M-498-SI25-M19 | B26: CAL-3973 | G26: 75640000
A27: RM-M-500-SI25-M19 | B27: CAL-3973 | G27: 67110003
A28: RM-M-505-SI25-M19 | B28: CAL-3977
A29: RM-M-504-SI25-M19 | B29: CAL-3977
A30: RM-M-508-SI25-M19 | B30: CAL-3978
A31: RM-M-510-SI25-M19 | B31: CAL-3978
A32: RM-M-502-SI25-M19 | B32: CAL-3983
A33: RM-M-503-SI25-M19 | B33: CAL-3983
A34: RM-M-526-SI25-M19 | B34: CAL-3988
A35: RM-M-527-SI25-M19 | B35: CAL-3988
A36: RM-M-519-SI25-M19 | B36: CAL-3987
A37: RM-M-520-SI25-M19 | B37: CAL-3987
A38: RM-J1094LI25-M19.1 | B38: A268029
A39: RM-J-1108LI25-M19.2 | B39: A268029
... A88: RM-M-584-SI25-M19 | B88: CAL-4081
...

Sheet CANCELADAS
A1: MEX125323 | B1: =VLOOKUP(A1,'CONSOLIDADO 2026'!H:H,1,0) -> #N/A
A2: MX-1070 | B2: =VLOOKUP(A2,'CONSOLIDADO 2026'!H:H,1,0) -> #N/A | J2: =J3/17.2988 -> 231.22991 | O2: 17.2988
A3: C7975 | B3: =VLOOKUP(A3,'CONSOLIDADO 2026'!H:H,1,0) -> #N/A | J3: 4000 | K3: 1101.44 | L3: 68.28 | M3: 147.54
A4: CAL-3748 | B4: =VLOOKUP(A4,'CONSOLIDADO 2026'!H:H,1,0) -> #N/A | E4: 540470091 | H4: POSITION | I4: NAME | J4: STANDING DESK | K4: COMPUTER | L4: KEYBOARD & MOUSE | M4: COMPUTER MONITOR
A5: MZO190087 | B5: =VLOOKUP(A5,'CONSOLIDADO 2026'!H:H,1,0) -> #N/A | H5: Compliance lead | I5: Alejandro Ocampo | J5: 1 | K5: 1 | L5: 1 | M5: 1
A6: MZO187863 | B6: =VLOOKUP(A6,'CONSOLIDADO 2026'!H:H,1,0) -> MZO187863 | H6: Compliance analyst | I6: Mayra García | J6: 1 | K6: 1 | L6: 1 | M6: 1
A7: MX-1088 | B7: =VLOOKUP(A7,'CONSOLIDADO 2026'!H:H,1,0) -> #N/A | H7: Compliance analyst | I7: TBD | J7: 1 | K7: 1 | L7: 1 | M7: 1
A8: CAL-4042 | B8: =VLOOKUP(A8,'CONSOLIDADO 2026'!H:H,1,0) -> #N/A | H8: Logistics Analyst | I8: Andrea Reyes | J8: 1 | K8: - | L8: 1 | M8: 1
A9: CAL-4056 | B9: =VLOOKUP(A9,'CONSOLIDADO 2026'!H:H,1,0) -> #N/A | H9: Logistics lead | I9: Magnolia Valle | J9: - | K9: - | L9: - | M9: 1
A10: CAL-4055 | B10: =VLOOKUP(A10,'CONSOLIDADO 2026'!H:H,1,0) -> #N/A | I10: TOTAL | J10: 4 | K10: 3 | L10: 4 | M10: 5
A11: CAL-4051 | B11: =VLOOKUP(A11,'CONSOLIDADO 2026'!H:H,1,0) -> #N/A | I11: TOTAL USD | J11: =J10*J2 -> 924.91965 | K11: =1101.44*3 -> 3304.32 | L11: =68.28*4 -> 273.12 | M11: =147.54*5 -> 737.7 | N11: =J11+K11+L11+M11 -> 5240.0596
A12: CAL-4048 | B12: =VLOOKUP(A12,'CONSOLIDADO 2026'!H:H,1,0) -> #N/A | K12: 21SYS5SW0J | L12: 4X31R64337 | M12: 63DEKAR3LA
A13: CAL-3983 | B13: CAL-4086 | K13: ThinkPad E14 G7, Intel® Core™ Ultra 5 235U vPro® (E-cores up to 4.10GHz, 12MB), 14" WUXGA Non-Touch, W11P64 US/UK_ENG, 32.0GB, 1x512GB SSD M.2 2242 PCIe Gen4 TLC Opal, Intel® Graphics, BT 5.3,Intel®AX211vPro, FPR, 1080PFHD Hybrid, 3 Cell Li-ion 48Wh, 65W, 3YR Premier NBD,1CourierCarryin, CO2 Offset,Keep your Drive, Black-Spanish (LA) | L13: Lenovo Professional Wireless Rechargeable Combo Keyboard and Mouse-LA Spanish | M13: ThinkVision S24i-30 23.8 inch Monitor
A14: CAL-4143
A15: CAL-4059
A16: 4996 | L16: SAGS 33306 | O16: INVOICE | P16: INVOICE | Q16: INVOICE | R16: INVOICE | S16: INVOICE | T16: INVOICE | U16: INVOICE
A17: CAL-4176 | I17: BU | J17: COM | K17: Sum of % | L17: 1266.32 | M17: 100 | N17: BU | O17: SAGS 33306 | P17: SAGS 33321 | Q17: SAGS 33310 | R17: SAGS 33322 | S17: SAGS 33323 | T17: SAGS 33251 | U17: SAGS 33267 | V17: TOTAL/MXN
A18: CAL-4172 | I18: 1 | J18: 2762703.6 | K18: 0.12331747 | L18: =(L17*M18)/M17 -> 156.13726 | M18: 12.33 | N18: 01 | O18: 202.06034 | P18: 202.06034 | Q18: 202.06034 | R18: 202.06034 | S18: 202.06034 | T18: 194.38738 | U18: 194.38738 | V18: =SUM(O18:U18) -> 1399.0765
A19: CAL-4174 | I19: 19 | J19: 14619078 | K19: 0.65254478 | L19: =(L18*M19)/M18 -> 826.2738 | M19: 65.25 | N19: 19 | O19: 1069.2974 | P19: 1069.2974 | Q19: 1069.2974 | R19: 1069.2974 | S19: 1069.2974 | T19: 1028.6924 | U19: 1028.6924 | V19: =SUM(O19:U19) -> 7403.8718
A20: CAL-4158 | I20: 23 | J20: 953212.61 | K20: 0.042548094 | L20: =(L19*M20)/M19 -> 53.8186 | M20: 4.25 | N20: 23 | O20: 69.647725 | P20: 69.647725 | Q20: 69.647725 | R20: 69.647725 | S20: 69.647725 | T20: 67.00295 | U20: 67.00295 | V20: =SUM(O20:U20) -> 482.24452
A21: FACTURA | B21: SEMANA | I21: 46 | J21: 1614005.6 | K21: 0.072043593 | L21: =(L20*M21)/M20 -> 91.301672 | M21: 7.21 | N21: 46 | O21: 118.15532 | P21: 118.15532 | Q21: 118.15532 | R21: 118.15532 | S21: 118.15532 | T21: 113.66853 | U21: 113.66853 | V21: =SUM(O21:U21) -> 818.11365
A22: CAL-4160 | B22: SEM 12 | C22: =VLOOKUP(A22,'CONSOLIDADO 2026'!H:H,1,0) -> CAL-4160 | I22: 61 | J22: 2118438.2 | K22: 0.094559711 | L22: =(L21*M22)/M21 -> 119.79387 | M22: 9.46 | N22: 61 | O22: 155.02764 | P22: 155.02764 | Q22: 155.02764 | R22: 155.02764 | S22: 155.02764 | T22: 149.14068 | U22: 149.14068 | V22: =SUM(O22:U22) -> 1073.4196
A23: CAL-4158 | B23: SEM 12 | C23: =VLOOKUP(A23,'CONSOLIDADO 2026'!H:H,1,0) -> CAL-4158 | I23: 62 | J23: 335741.98 | K23: 0.014986354 | L23: =(L22*M23)/M22 -> 18.9948 | M23: 1.5 | N23: 62 | O23: 24.58155 | P23: 24.58155 | Q23: 24.58155 | R23: 24.58155 | S23: 24.58155 | T23: 23.6481 | U23: 23.6481 | V23: =SUM(O23:U23) -> 170.20395
A24: CAL-4185 | B24: SEM 13 | C24: =VLOOKUP(A24,'CONSOLIDADO 2026'!H:H,1,0) -> CAL-4185 | I24: Grand Total | J24: 22403180 | K24: 1 | L24: =SUM(L18:L23) -> 1266.32 | M24: =SUM(M18:M23) -> 100 | O24: =SUM(O18:O23) -> 1638.77 | P24: =SUM(P18:P23) -> 1638.77 | Q24: =SUM(Q18:Q23) -> 1638.77 | R24: =SUM(R18:R23) -> 1638.77 | S24: =SUM(S18:S23) -> 1638.77 | T24: =SUM(T18:T23) -> 1576.54 | U24: =SUM(U18:U23) -> 1576.54 | V24: =SUM(V18:V23) -> 11346.93
A25: CAL-4169 | C25: =VLOOKUP(A25,'CONSOLIDADO 2026'!H:H,1,0) -> #N/A
A26: CAL-4170 | C26: =VLOOKUP(A26,'CONSOLIDADO 2026'!H:H,1,0) -> #N/A | O26: INVOICE | P26: INVOICE | Q26: INVOICE | R26: INVOICE | S26: INVOICE | T26: INVOICE | U26: INVOICE | V26: INVOICE | W26: INVOICE | X26: INVOICE | Y26: INVOICE | Z26: INVOICE | AA26: INVOICE | AB26: INVOICE | AC26: INVOICE | AD26: INVOICE | AE26: INVOICE | AF26: INVOICE | AG26: INVOICE | AH26: INVOICE
A27: CAL-4171 | C27: =VLOOKUP(A27,'CONSOLIDADO 2026'!H:H,1,0) -> #N/A | N27: BU | O27: SAGS 33614 | P27: SAGS 33605 | Q27: SAGS 33592 | R27: SAGS 33600 | S27: SAGS 33604 | T27: SAGS 33603 | U27: SAGS 33598 | V27: SAGS 33588 | W27: SAGS 33587 | X27: SAGS 33597 | Y27: SAGS 33595 | Z27: SAGS 33591 | AA27: SAGS 33594 | AB27: SAGS 33613 | AC27: SAGS 33606 | AD27: SAGS 33586 | AE27: SAGS 33593 | AF27: SAGS 33590 | AG27: SAGS 33607 | AH27: SAGS 33589 | AI27: TOTAL/MXN
A28: CAL-4172 | C28: =VLOOKUP(A28,'CONSOLIDADO 2026'!H:H,1,0) -> #N/A | N28: 01 | O28: 214.39034 | P28: 214.39034 | Q28: 276.04034 | R28: 276.04034 | S28: 276.04034 | T28: 265.84713 | U28: 276.04034 | V28: 214.39034 | W28: 276.04034 | X28: 276.04034 | Y28: 276.04034 | Z28: 276.04034 | AA28: 276.04034 | AB28: 276.04034 | AC28: 276.04034 | AD28: 276.04034 | AE28: 276.04034 | AF28: 276.04034 | AG28: 2959.2 | AH28: 276.04034 | AI28: =SUM(O28:AH28) -> 8008.8233
A29: CAL-4174 | C29: =VLOOKUP(A29,'CONSOLIDADO 2026'!H:H,1,0) -> #N/A | N29: 19 | O29: 1134.5474 | P29: 1134.5474 | Q29: 1460.7974 | R29: 1460.7974 | S29: 1460.7974 | T29: 1406.8553 | U29: 1460.7974 | V29: 1134.5474 | W29: 1460.7974 | X29: 1460.7974 | Y29: 1460.7974 | Z29: 1460.7974 | AA29: 1460.7974 | AB29: 1460.7974 | AC29: 1460.7974 | AD29: 1460.7974 | AE29: 1460.7974 | AF29: 1460.7974 | AG29: 15660 | AH29: 1460.7974 | AI29: =SUM(O29:AH29) -> 42382.459
A30: CAL-4175 | C30: =VLOOKUP(A30,'CONSOLIDADO 2026'!H:H,1,0) -> #N/A | N30: 23 | O30: 73.897725 | P30: 73.897725 | Q30: 95.147725 | R30: 95.147725 | S30: 95.147725 | T30: 91.63425 | U30: 95.147725 | V30: 73.897725 | W30: 95.147725 | X30: 95.147725 | Y30: 95.147725 | Z30: 95.147725 | AA30: 95.147725 | AB30: 95.147725 | AC30: 95.147725 | AD30: 95.147725 | AE30: 95.147725 | AF30: 95.147725 | AG30: 1020 | AH30: 95.147725 | AI30: =SUM(O30:AH30) -> 2760.5433
A31: CAL-4176 | C31: =VLOOKUP(A31,'CONSOLIDADO 2026'!H:H,1,0) -> #N/A | N31: 46 | O31: 125.36532 | P31: 125.36532 | Q31: 161.41532 | R31: 161.41532 | S31: 161.41532 | T31: 155.45481 | U31: 161.41532 | V31: 125.36532 | W31: 161.41532 | X31: 161.41532 | Y31: 161.41532 | Z31: 161.41532 | AA31: 161.41532 | AB31: 161.41532 | AC31: 161.41532 | AD31: 161.41532 | AE31: 161.41532 | AF31: 161.41532 | AG31: 1730.4 | AH31: 161.41532 | AI31: =SUM(O31:AH31) -> 4683.1805
A32: CAL-4146 | C32: =VLOOKUP(A32,'CONSOLIDADO 2026'!H:H,1,0) -> #N/A | N32: 61 | O32: 164.48764 | P32: 164.48764 | Q32: 211.78764 | R32: 211.78764 | S32: 211.78764 | T32: 203.96706 | U32: 211.78764 | V32: 164.48764 | W32: 211.78764 | X32: 211.78764 | Y32: 211.78764 | Z32: 211.78764 | AA32: 211.78764 | AB32: 211.78764 | AC32: 211.78764 | AD32: 211.78764 | AE32: 211.78764 | AF32: 211.78764 | AG32: 2270.4 | AH32: 211.78764 | AI32: =SUM(O32:AH32) -> 6144.6446
A33: MX-1110 | C33: =VLOOKUP(A33,'CONSOLIDADO 2026'!H:H,1,0) -> #N/A | N33: 62 | O33: 26.08155 | P33: 26.08155 | Q33: 33.58155 | R33: 33.58155 | S33: 33.58155 | T33: 32.3415 | U33: 33.58155 | V33: 26.08155 | W33: 33.58155 | X33: 33.58155 | Y33: 33.58155 | Z33: 33.58155 | AA33: 33.58155 | AB33: 33.58155 | AC33: 33.58155 | AD33: 33.58155 | AE33: 33.58155 | AF33: 33.58155 | AG33: 360 | AH33: 33.58155 | AI33: =SUM(O33:AH33) -> 974.3094
O34: =SUM(O28:O33) -> 1738.77 | P34: =SUM(P28:P33) -> 1738.77 | Q34: =SUM(Q28:Q33) -> 2238.77 | R34: =SUM(R28:R33) -> 2238.77 | S34: =SUM(S28:S33) -> 2238.77 | T34: =SUM(T28:T33) -> 2156.1 | U34: =SUM(U28:U33) -> 2238.77 | V34: =SUM(V28:V33) -> 1738.77 | ... AH34: =SUM(AH28:AH33) -> 2238.77 | AI34: =SUM(O34:AH34) -> 64953.96
A35: CAL-4185 Sustituye CAL 4190
B36: Trading | O36: INVOICE | P36: INVOICE | Q36: INVOICE | R36: INVOICE | S36: INVOICE | T36: INVOICE | U36: INVOICE | V36: INVOICE
A37: F 66896 | B37: F 65719 | N37: BU | O37: SAGS 33654 | P37: SAGS 33652 | Q37: 214.39034 | R37: SAGS 33650 | S37: SAGS 33649 | T37: SAGS 33648 | U37: SAGS 33647 | V37: SAGS 33661
A38: F 66897 | B38: F 65295 | N38: 01 | O38: 265.84713 | P38: 265.84713 | Q38: 214.39034 | R38: 276.04034 | S38: 276.04034 | T38: 276.04034 | U38: 265.84713 | V38: 508.19451 | W38: =SUM(O38:V38) -> 2348.2473
A39: F 66898 | B39: F 65296 | N39: 19 | O39: 1406.8553 | P39: 1406.8553 | Q39: 1134.5474 | R39: 1460.7974 | S39: 1460.7974 | T39: 1460.7974 | U39: 1406.8553 | V39: 2689.3505 | W39: =SUM(O39:V39) -> 12426.856
A40: F 66899 | B40: F 65297 | N40: 23 | O40: 91.63425 | P40: 91.63425 | Q40: 73.897725 | R40: 95.147725 | S40: 95.147725 | T40: 95.147725 | U40: 91.63425 | V40: 175.16842 | W40: =SUM(O40:V40) -> 809.41207
...

Sheet CHINA
A1: Document Number | B1: Customer PO# | C1: Document Date | D1: Curr | E1: Outstanding Amount | F1: BU | G1: CTA | H1: CS000008981 | I1: =E2 -> 15631.1 | L1: CS000008981 | M1: 15618 | N1: Sebastian | R1: PFA | S1: Status | T1: PFA Cost | U1: Cuenta | V1: BU | W1: Invoice | X1: Invoice Amount
A2: 101011381293-F | B2: CS000008981 | C2: 46045 | D2: USD | E2: 15631.1 | F2: M23 | G2: 67180000 | H2: CS000009049 | I2: =E5+E10 -> 38602.6 | J2: =I7+I8+I10 -> 11537.1 | K2: =I2+J2 -> 50139.7 | L2: CS000009049 | M2: 58840 | N2: Marcos | R2: CS000009380 | S2: Approved | T2: 615 | U2: 67180000 | V2: M01 | W2: 101513735151-60F | X2: 1171.2 | AC2: Estos PFA se deben cobrar a ABC cuando se tengan las facturas completas de China.
A3: 101513721978-32F | B3: CS000009049 | C3: 46048 | D3: USD | E3: 27697.1 | F3: M23 | G3: 67180000 | H3: CS000009051 | I3: =E12 -> 1072 | J3: =M3-I3 -> 2176 | K3: =I3+J3 -> 3248 | L3: CS000009051 | M3: 3248 | N3: Marcos | R3: CS000009381 | S3: Approved | T3: 602 | U3: 67180000 | V3: M01
B4: CS9049+9051 | C4: 46048 | D4: USD | E4: 3169.1 | F4: M23 | G4: 67180000 | H4: CS000009050 | I4: =E6 -> 2023 | L4: CS000009050 | M4: 2380 | N4: Marcos | R4: CS000009382 | S4: Approved | T4: 4832 | U4: 67180000 | V4: M01 | W4: 101513753573-F | X4: 15097.6
B5: CS000009049 | C5: 46048 | D5: USD | E5: 17976 | F5: M23 | G5: 67180000 | H5: CS000009048 | I5: =E7 -> 4529 | J5: 3401.6 | K5: =I5+J5 -> 7930.6 | L5: CS000009048 | M5: 13584 | N5: Marcos | R5: CS000009385 | S5: Approved | T5: 4832 | U5: 67180000 | V5: M01
B6: CS000009050 | C6: 46048 | D6: USD | E6: 2023 | F6: M23 | G6: 67180000 | K6: =I1+K2+K3+I4+K5 -> 78972.4 | M6: =SUM(M1:M5) -> 93670 | R6: CS000009386 | S6: Approved | T6: 4832 | U6: 67180000 | V6: M01
B7: CS000009048 | C7: 46048 | D7: USD | E7: 4529 | F7: M23 | G7: 67180000 | I7: =E4-J7 -> 2081.1 | J7: =J3/2 -> 1088 | R7: CS000009437 | S7: Approved | T7: 22125 | U7: 67180000 | V7: M01
A8: 101513722893-37F | B8: CS000009049 | C8: 46048 | D8: USD | E8: 35644.2 | F8: M23 | G8: 67180000 | I8: =E9-J7 -> 6054.4 | M8: =M6-K6 -> 14697.6 | R8: CS000009542 | S8: Approved | T8: 28100 | U8: 67180000 | V8: M01 | W8: 101513751656-38F | X8: 15104
B9: CS9049+9051 | C9: 46048 | D9: USD | E9: 7142.4 | F9: M23 | G9: 67180000 | J9: =M2-K2 -> 8700.3 | K9: CS000009049 | T9: =SUM(T2:T8) -> 65938 | X9: =X2+X4+X8 -> 31372.8
B10: CS000009049 | C10: 46048 | D10: USD | E10: 20626.6 | F10: M23 | G10: 67180000 | I10: =E11/2 -> 3401.6
B11: CS9048+9049 | C11: 46048 | D11: USD | E11: 6803.2 | F11: M23 | G11: 67180000 | J11: =M5-K5 -> 5653.4 | K11: CS000009048 | R11: 9330 Y 9601 | S11: SE DEBEN COBRAR JUNTOS
B12: CS000009051 | C12: 46048 | D12: USD | E12: 1072 | F12: M23 | G12: 67180000
A13: AP101DN260011 | B13: DHL FREIGHT CHARGE | C13: 46048 | D13: USD | E13: 604.88 | F13: M19 | G13: 67180000
E14: =E2+E3+E8+E13 -> 79577.28
A15: Document Number | B15: Customer PO# | C15: Document Date | D15: Curr | E15: Outstanding Amount | F15: BU | G15: CTA
A16: 101513735151-60F | B16: CS000009049 | C16: 46077 | D16: USD | E16: 3840 | F16: M23 | G16: 67180000 | H16: CS000009049 | I16: =E16 -> 3840 | L16: CS000009049 | M16: 58840 | N16: Marcos
B17: CS000009048 | C17: 46077 | D17: USD | E17: 2726.4 | F17: M23 | G17: 67180000 | H17: CS000009048 | I17: =E17 -> 2726.4 | K17: =E7+E17+E28 -> 9988.2 | L17: CS000009048 | M17: 13584 | N17: Marcos
B18: CS000009388 | C18: 46077 | D18: USD | E18: 2009.6 | F18: M23 | G18: 67180000 | H18: CS000009388 | I18: =E18 -> 2009.6 | L18: CS000009388 | M18: 1984 | N18: Marcos
B19: CS9380+9381 | C19: 46077 | D19: USD | E19: 1171.2 | F19: M01 | G19: 67180000 | H19: CS000009380 | I19: =E19/2 -> 585.6 | L19: CS000009380 | M19: 615 | N19: Juan Pablo
B20: CS000009505 | C20: 46077 | D20: USD | E20: 8528 | F20: M19 | G20: 67180000 | H20: CS000009381 | I20: =E19/2 -> 585.6 | L20: CS000009381 | M20: 602 | N20: Juan Pablo
B21: CS000009505 | C21: 46077 | D21: USD | E21: 7104 | F21: M19 | G21: 67180000 | H21: CS000009505 | I21: =E20+E21+E22 -> 22736 | J21: =M21-I21 -> -14396 | L21: CS000009505 | M21: 8340 | N21: Arturo
B22: CS000009505 | C22: 46077 | D22: USD | E22: 7104 | F22: M19 | G22: 67180000 | H22: CS000009506 | I22: =E23 -> 8528 | L22: CS000009506 | M22: 19111 | N22: Arturo
B23: CS000009506 | C23: 46077 | D23: USD | E23: 8528 | F23: M19 | G23: 67180000 | H23: CS000009482 | I23: =E24 -> 17670.4 | L23: CS000009482 | M23: 17242 | N23: Sebastian
A24: 101011392811-12F | B24: CS000009482 | C24: 45713 | D24: USD | E24: 17670.4 | F24: M46 | G24: 67180000 | I24: =SUM(I16:I23) -> 58681.6
E25: =SUM(E16:E24) -> 58681.6
A27: Document Number | B27: Customer PO# | C27: Document Date | D27: Curr | E27: Outstanding Amount | F27: BU | G27: CTA
A28: 101513751656-38F | B28: CS000009048 | C28: 46107 | D28: USD | E28: 2732.8 | F28: M23 | G28: 67180000 | H28: CS000009048 | I28: 13584 | J28: Marcos
B29: CS000009506 | C29: 46107 | D29: USD | E29: 1433.6 | F29: M19 | G29: 67180000 | H29: CS000009506 | I29: 19111 | J29: Arturo
B30: CS000009542 | C30: 46107 | D30: USD | E30: 15104 | F30: M01 | G30: 67180000 | H30: CS000009542 | I30: 28100 | J30: Juan Pablo
B31: CS000009635 | C31: 46107 | D31: USD | E31: 2124.8 | F31: M19 | G31: 67180000 | H31: CS000009635 | I31: 1067 | J31: Arturo
A32: AP101DN260134 | B32: CS000009383 | C32: 46107 | D32: USD | E32: 2334.04 | F32: M19 | G32: 67180000
B33: CS000009898
H35: CS000009806 | I35: 1736 | K35: =4*31 -> 124
H36: CS000009805 | I36: 3432
H37: CS000009804 | I37: 31200
H38: CS000009803 | I38: 1336
I39: =SUM(I35:I38) -> 37704
H41: CS000009996
H42: CS000010007

Sheet NISS
A1: Date of invoice | B1: Date of export | C1: wk no | D1: PN | E1: Customer PO (Movex) | F1: DN | G1: ORACLE ORDER | H1: Quantity | I1: REV | J1: Invoice no | K1: Amount | L1: Freight cost | M1: Total Amount | N1: PLL | O1: CTN | P1: Nett | Q1: Gross | R1: Incoterms | S1: E-broj | T1: Customer number | U1: Bill to | V1: Ship to | W1: PFA | X1: Container No
A2: 45842 | B2: 45842 | C2: 27 | D2: 1663-5YY0194-MTEN/RS | F2: 2910069209 | G2: 1197004349 | H2: 2592 | I2: D | J2: 14745C | L2: 1295.49 | M2: 0.49980324 | N2: 2 | O2: 24 | P2: 189.22 | Q2: 323.9 | R2: CPT ALTAMIRA | S2: E-17349 | T2: W_34798 | U2: JENA | V2: Mexico | X2: SARU0013110 | AC2: 226 | AL2: PFA # | AM2: Status | AN2: Origin Company Name | AO2: Origin Country | AP2: Item Code | AQ2: Item Description | AR2: Quantity (pcs) | AS2: Bill to Cost Center (Primary)
A3: 45842 | B3: 45842 | C3: 27 | D3: 1663-5YY0194-MTEN/RS | F3: 2910069210 | G3: 3197001993 | H3: 2592 | I3: D | J3: 14746C | L3: 1295.49 | M3: 0.49980324 | N3: 2 | O3: 24 | P3: 189.22 | Q3: 323.9 | R3: CPT ALTAMIRA | S3: E-17349 | T3: W_34798 | U3: JENA | V3: Mexico | X3: SARU0013110 | AC3: 226 | AL3: CS000009615 | AM3: Approved | AN3: Johnson Electric d.o.o. Nis | AO3: Serbia | AP3: 1663-5YY0294ENNV00 | AQ3: PCBA | AR3: 30720 | AS3: Americas: APG PC MEXICO
A4: 45842 | B4: 45842 | C4: 27 | D4: 1663-5YY0294-H01 | F4: 2910069211 | G4: 1197004354 | H4: 6208 | I4: E | J4: 14752C | L4: 1150.18 | M4: 0.18527384 | N4: 2 | O4: 20 | P4: 130.37 | Q4: 287.57 | R4: CPT ALTAMIRA | S4: E-17349 | T4: W_34798 | U4: JENA | V4: Mexico | X4: SARU0013110 | AC4: 226 | AL4: CS000009614 | AM4: Pending 1st Level Approval | AN4: Johnson Electric d.o.o. Nis | AO4: Serbia | AP4: 1663-5YY0499ENNV00 | AQ4: PCBA | AR4: 10560 | AS4: Americas: APG- PC- Springfield
A5: 45842 | B5: 45842 | C5: 27 | D5: 1663-5YY0271EN | F5: 2910069212 | G5: 3197002016 | H5: 2112 | I5: G | J5: 14747C | L5: 723.85 | M5: 0.34273201 | N5: 1 | O5: 12 | P5: 80.26 | Q5: 180.98 | R5: CPT ALTAMIRA | S5: E-17349 | T5: W_34798 | U5: JENA | V5: Mexico | X5: SARU0013110 | AC5: 226 | AL5: CS000009613 | AM5: Approved | AN5: Johnson Electric d.o.o. Nis | AO5: Serbia | AP5: 1663-5YY0250ENNV00 | AQ5: PCBA | AR5: 8448 | AS5: Americas: APG- PC- Springfield
A6: 45842 | B6: 45842 | C6: 27 | D6: 1663-5YY0271EN | F6: 2910069213 | G6: 3197002020 | H6: 2112 | I6: G | J6: 14748C | L6: 723.85 | M6: 0.34273201 | N6: 1 | O6: 12 | P6: 80.26 | Q6: 180.98 | R6: CPT ALTAMIRA | S6: E-17349 | T6: W_34798 | U6: JENA | V6: Mexico | X6: SARU0013110 | AC6: 226 | AL6: CS000009612 | AM6: Approved | AN6: Johnson Electric d.o.o. Nis | AO6: Serbia | AP6: 1663-5YY0122ENNV00 | AQ6: PCBA | AR6: 3456 | AS6: Americas: APG PC MEXICO
A7: 45842 | B7: 45842 | C7: 27 | D7: 1663-5YY0274EN | F7: 2910069214 | G7: 1197004352 | H7: 2112 | I7: H | J7: 14749C | L7: 723.85 | M7: 0.34273201 | N7: 1 | O7: 12 | P7: 80.26 | Q7: 180.98 | R7: CPT ALTAMIRA | S7: E-17349 | T7: W_34798 | U7: JENA | V7: Mexico | X7: SARU0013110 | AC7: 226 | AL7: CS000009531 | AM7: Approved | AN7: Johnson Electric d.o.o. Nis | AO7: Serbia | AP7: 1663-5YY0296ENNV13 | AQ7: PCBA | AR7: 4224 | AS7: Americas: APG- PC BRAZIL
A8: 45842 | B8: 45842 | C8: 27 | D8: 1663-5YY0274EN | F8: 2910069215 | G8: 3197001996 | H8: 4224 | I8: H | J8: 14750C | L8: 1447.7 | M8: 0.34273201 | N8: 2 | O8: 24 | P8: 160.51 | Q8: 361.95 | R8: CPT ALTAMIRA | S8: E-17349 | T8: W_34798 | U8: JENA | V8: Mexico | X8: SARU0013110 | AC8: 226 | AL8: CS000009530 | AM8: Approved | AN8: Johnson Electric d.o.o. Nis | AO8: Serbia | AP8: 1663-5YY0294ENNV00 | AQ8: PCBA | AR8: 23040 | AS8: Americas: APG PC MEXICO
A9: 45842 | B9: 45842 | C9: 27 | D9: 1663-5YY0333EN | F9: 2910069216 | G9: 3197002018 | H9: 3840 | I9: C | J9: 14751C | L9: 686.03 | M9: 0.17865365 | N9: 1 | O9: 12 | P9: 76.8 | Q9: 167 | R9: CPT ALTAMIRA | S9: E-17349 | T9: W_34798 | U9: JENA | V9: Mexico | X9: SARU0013110 | AC9: 226 | AL9: CS000009529 | AM9: Approved | AN9: Johnson Electric d.o.o. Nis | AO9: Serbia | AP9: 1663-5YY0250ENNV00 | AQ9: PCBA | AR9: 8448 | AS9: Americas: APG- PC- Springfield
A10: 45847 | B10: 45847 | C10: 28 | D10: 1663-5YY0196EN | F10: 2910069305 | G10: 3197001989 | H10: 613 | I10: D | J10: 14781C | L10: 1629.95 | M10: 2.6589723 | N10: 1 | O10: 6 | P10: 58.84 | Q10: 103 | R10: CPT ALTAMIRA | S10: E-17415 | T10: W_34798 | U10: JENA | V10: Mexico | W10: CS000007888 | X10: avio | AC10: 228
A11: 45849 | B11: 45849 | C11: 28 | D11: 1663-5YY0122EN/RS | F11: 2910069396 | G11: 1197004322 | H11: 3456 | I11: B | J11: 14815C | L11: 1062.64 | M11: 0.30747685 | N11: 2 | O11: 24 | P11: 248.83 | Q11: 398 | R11: CPT ALTAMIRA | S11: E-17388 | T11: W_34798 | U11: JENA | V11: Mexico | X11: GESU5563043 | AC11: 229
A12: 45849 | B12: 45849 | C12: 28 | D12: 1663-5YY0247EN/RS | F12: 2910069397 | G12: 3197001983 | H12: 6912 | I12: B | J12: 14816C | L12: 2125.28 | M12: 0.30747685 | N12: 4 | O12: 48 | P12: 497.66 | Q12: 804 | R12: CPT ALTAMIRA | S12: E-17388 | T12: W_34798 | U12: JENA | V12: Mexico | X12: GESU5563043 | AC12: 229
A13: 45849 | B13: 45849 | C13: 28 | D13: 1663-5YY0247EN/RS | F13: 2910069398 | G13: 3197001974 | H13: 1728 | I13: B | J13: 14817C | L13: 531.32 | M13: 0.30747685 | N13: 1 | O13: 12 | P13: 124.42 | Q13: 201 | R13: CPT ALTAMIRA | S13: E-17388 | T13: W_34798 | U13: JENA | V13: Mexico | X13: GESU5563043 | AC13: 229
A14: 45849 | B14: 45849 | C14: 28 | D14: 1663-5YY0318EN | F14: 2910069399 | G14: 1197004357 | H14: 2016 | I14: C | J14: 14818C | L14: 393.52 | M14: 0.19519841 | N14: 1 | O14: 12 | P14: 53.43 | Q14: 142.02 | R14: CPT ALTAMIRA | S14: E-17388 | T14: W_34798 | U14: JENA | V14: Mexico | X14: GESU5563043 | AC14: 229
A15: 45849 | B15: 45849 | C15: 28 | D15: 1663-5YY0333EN | F15: 2910069400 | G15: 3197002017 | H15: 3840 | I15: C | J15: 14819C | L15: 475.25 | M15: 0.12376302 | N15: 1 | O15: 12 | P15: 76.8 | Q15: 167 | R15: CPT ALTAMIRA | S15: E-17388 | T15: W_34798 | U15: JENA | V15: Mexico | X15: GESU5563043 | AC15: 229
A16: 45849 | B16: 45849 | C16: 28 | D16: 1663-5YY0445EN | F16: 2910069401 | G16: 3197001966 | H16: 2592 | I16: E | J16: 14822C | L16: 930.42 | M16: 0.35895833 | N16: 2 | O16: 24 | P16: 181.44 | Q16: 316 | R16: CPT ALTAMIRA | S16: E-17388 | T16: W_34798 | U16: JENA | V16: Mexico | X16: GESU5563043 | AC16: 229
A17: 45849 | B17: 45849 | C17: 28 | D17: 1663-5YY0445EN | F17: 2910069402 | G17: 1197004330 | H17: 1296 | I17: E | J17: 14823C | L17: 465.21 | M17: 0.35895833 | N17: 1 | O17: 12 | P17: 90.72 | Q17: 158 | R17: CPT ALTAMIRA | S17: E-17388 | T17: W_34798 | U17: JENA | V17: Mexico | X17: GESU5563043 | AC17: 229
A18: 45849 | B18: 45849 | C18: 28 | D18: 1663-5YY0445EN | F18: 2910069403 | G18: 3197001987 | H18: 2592 | I18: E | J18: 14824C | L18: 930.42 | M18: 0.35895833 | N18: 2 | O18: 24 | P18: 181.44 | Q18: 316 | R18: CPT ALTAMIRA | S18: E-17388 | T18: W_34798 | U18: JENA | V18: Mexico | X18: GESU5563043 | AC18: 229
A19: 45849 | B19: 45849 | C19: 28 | D19: 1663-5YY0445EN | F19: 2910069404 | G19: 1197004348 | H19: 1137 | I19: E | J19: 14825C | L19: 422.32 | M19: 0.3714336 | N19: 1 | O19: 11 | P19: 79.59 | Q19: 137 | R19: CPT ALTAMIRA | S19: E-17388 | T19: W_34798 | U19: JENA | V19: Mexico | X19: GESU5563043 | AC19: 229
A20: 45849 | B20: 45849 | C20: 28 | D20: 1663-5YY0078EN/RS | F20: 2910069405 | G20: 3197002025 | H20: 1728 | I20: D | J20: 14821C | L20: 520.91 | M20: 0.30145255 | N20: 1 | O20: 12 | P20: 0 | Q20: 132.92 | R20: CPT ALTAMIRA | S20: E-17388 | T20: W_34798 | U20: JENA | V20: Mexico | X20: GESU5563043 | AC20: 229
A21: 45849 | B21: 45849 | C21: 28 | D21: 1663-5YY0061EN/RS | F21: 2910069406 | G21: 3197001988 | H21: 657 | I21: G | J21: 14820C | L21: 120.15 | M21: 0.18287671 | N21: 1 | O21: 5 | P21: 43.34 | Q21: 86 | R21: CPT ALTAMIRA | S21: E-17388 | T21: W_34798 | U21: JENA | V21: Mexico | X21: GESU5563043 | AC21: 229
A22: 45856 | B22: 45856 | C22: 29 | D22: 1663-5YY0194-MTEN/RS | F22: 2910069584 | G22: 3197002046 | H22: 2592 | I22: D | J22: 14913C | L22: 714.49 | M22: 0.27565201 | N22: 2 | O22: 24 | P22: 189.22 | Q22: 323.9 | R22: CPT ALTAMIRA | S22: E-17432 | T22: W_34798 | U22: JENA | V22: Mexico | X22: MSDU8734823 | AC22: 230
... A49: 45863 | B49: 45863 | C49: 30 | D49: 1663-5YY0333EN | F49: 2910069793 | G49: 3197002023 | H49: 7680 | I49: C | J49: 15026C | L49: 898.88 | M49: 0.11704167 | N49: 2 | O49: 24 | P49: 153.6 | Q49: 343.04 | R49: CPT ALTAMIRA | S49: E-17445 | T49: W_34798 | U49: JENA | V49: Mexico | X49: TGCU0233629 | AC49: 232
A50: 45867 | B50: 45867 | C50: 31 | D50: 1663-5YY0262EN/RS | F50: 2910069841 | G50: 3197002032 | H50: 1008 | I50: A | J50: 15038C | L50: 3923 | M50: 3.8918651 | N50: 1 | O50: 7 | P50: 83.66 | Q50: 121 | R50: CPT ALTAMIRA | S50: E-17519 | T50: W_34798 | U50: JENA | V50: Mexico | W50: CS000008061 | X50: avio | AC50: 233
A51: 45869 | B51: 45869 | C51: 31 | D51: 1663-5YY0257-H02 | F51: 2910069862 | G51: 3197001995 | H51: 3840 | I51: H | J51: 15040C | L51: 1541.5 | M51: 0.40143229 | N51: 1 | O51: 12 | P51: 84.48 | Q51: 163 | R51: CPT ALTAMIRA | S51: E-17524 | T51: W_34798 | U51: JENA | V51: Mexico | W51: CS000007967 | X51: avio | AC51: 234
A52: 45869 | B52: 45869 | C52: 31 | D52: 1663-5YY0257-H02 | F52: 2910069863 | G52: 1197004356 | H52: 3840 | I52: H | J52: 15041C | L52: 1541.5 | M52: 0.40143229 | N52: 1 | O52: 12 | P52: 84.48 | Q52: 162 | R52: CPT ALTAMIRA | S52: E-17524 | T52: W_34798 | U52: JENA | V52: Mexico | W52: CS000007967 | X52: avio | AC52: 234
A53: 45876 | B53: 45876 | C53: 32 | D53: 1663-5YY0257-H02 | F53: 2910069897 | G53: 1197004347 | H53: 3200 | I53: H | J53: 15044C | L53: 4893.18 | M53: 1.5291188 | N53: 1 | O53: 10 | P53: 70.4 | Q53: 139 | R53: CPT ALTAMIRA | S53: E-17532 | T53: W_34798 | U53: JENA | V53: Mexico | W53: CS000007887 | X53: avio | AC53: 236
A54: 45876 | B54: 45876 | C54: 32 | D54: 1663-5YY0257-H02 | F54: 2910069898 | G54: 3197001964 | H54: 1549 | I54: H | J54: 15045C | L54: 2813.26 | M54: 1.8161782 | N54: 1 | O54: 5 | P54: 34.08 | Q54: 79 | R54: CPT ALTAMIRA | S54: E-17532 | T54: W_34798 | U54: JENA | V54: Mexico | W54: CS000007887 | X54: avio | AC54: 236
A55: 45877 | B55: 45881 | C55: 32 | D55: 1663-5YY0294-H01 | F55: 2910069923 | G55: 3197002051 | H55: 3840 | I55: E | J55: 15059C | L55: 580.23 | M55: 0.15110156 | N55: 1 | O55: 12 | P55: 80.64 | Q55: 177 | R55: CPT ALTAMIRA | S55: E-17473 | T55: W_34798 | U55: JENA | V55: Mexico | X55: MSDU6387941 | AC55: 237
A56: 45877 | B56: 45881 | C56: 32 | D56: 1663-5YY0294-H01 | F56: 2910069924 | G56: 3197002043 | H56: 3840 | I56: E | J56: 15060C | L56: 580.23 | M56: 0.15110156 | N56: 1 | O56: 12 | P56: 80.64 | Q56: 177 | R56: CPT ALTAMIRA | S56: E-17473 | T56: W_34798 | U56: JENA | V56: Mexico | X56: MSDU6387941 | AC56: 237
A57: 45877 | B57: 45881 | C57: 32 | D57: 1663-5YY0122EN/RS | F57: 2910069925 | G57: 1197004322 | H57: 771 | I57: B | J57: 15050C | L57: 342.02 | M57: 0.44360571 | N57: 1 | O57: 6 | P57: 55.51 | Q57: 98 | R57: CPT ALTAMIRA | S57: E-17473 | T57: W_34798 | U57: JENA | V57: Mexico | X57: MSDU6387941 | AC57: 237
A58: 45877 | B58: 45881 | C58: 32 | D58: 1663-5YY0247EN/RS | F58: 2910069926 | G58: 1197004331 | H58: 5184 | I58: B | J58: 15051C | L58: 1963.93 | M58: 0.37884452 | N58: 3 | O58: 36 | P58: 373.25 | Q58: 603 | R58: CPT ALTAMIRA | S58: E-17473 | T58: W_34798 | U58: JENA | V58: Mexico | X58: MSDU6387941 | AC58: 237
A59: 45877 | B59: 45881 | C59: 32 | D59: 1663-5YY0247EN/RS | F59: 2910069927 | G59: 3197002062 | H59: 2953 | I59: B | J59: 15052C | L59: 1146.95 | M59: 0.38840163 | N59: 2 | O59: 21 | P59: 212.62 | Q59: 344 | R59: CPT ALTAMIRA | S59: E-17473 | T59: W_34798 | U59: JENA | V59: Mexico | X59: MSDU6387941 | AC59: 237
A60: 45877 | B60: 45881 | C60: 32 | D60: 1663-5YY0268-H02 | F60: 2910069928 | G60: 1197004388 | H60: 2016 | I60: H | J60: 15058C | L60: 451.51 | M60: 0.22396329 | N60: 1 | O60: 12 | P60: 54.43 | Q60: 140 | R60: CPT ALTAMIRA | S60: E-17473 | T60: W_34798 | U60: JENA | V60: Mexico | X60: MSDU6387941 | AC60: 237
A61: 45877 | B61: 45881 | C61: 32 | D61: 1663-5YY0274EN | F61: 2910069929 | G61: 3197002042 | H61: 2112 | I61: H | J61: 15053C | L61: 617.84 | M61: 0.29253788 | N61: 1 | O61: 12 | P61: 80.26 | Q61: 180.98 | R61: CPT ALTAMIRA | S61: E-17473 | T61: W_34798 | U61: JENA | V61: Mexico | X61: MSDU6387941 | AC61: 237
A62: 45877 | B62: 45881 | C62: 32 | D62: 1663-5YY0274EN | F62: 2910069930 | G62: 3197002038 | H62: 2112 | I62: H | J62: 15054C | L62: 617.84 | M62: 0.29253788 | N62: 1 | O62: 12 | P62: 80.26 | Q62: 180.98 | R62: CPT ALTAMIRA | S62: E-17473 | T62: W_34798 | U62: JENA | V62: Mexico | X62: MSDU6387941 | AC62: 237
A63: 45877 | B63: 45881 | C63: 32 | D63: 1663-5YY0274EN | F63: 2910069931 | G63: 1197004413 | H63: 2112 | I63: H | J63: 15055C | L63: 617.84 | M63: 0.29253788 | N63: 1 | O63: 12 | P63: 80.26 | Q63: 180.98 | R63: CPT ALTAMIRA | S63: E-17473 | T63: W_34798 | U63: JENA | V63: Mexico | X63: MSDU6387941 | AC63: 237
A64: 45877 | B64: 45881 | C64: 32 | D64: 1663-5YY0333EN | F64: 2910069932 | G64: 1197004405 | H64: 3840 | I64: C | J64: 15057C | L64: 585.56 | M64: 0.15248958 | N64: 1 | O64: 12 | P64: 76.8 | Q64: 167 | R64: CPT ALTAMIRA | S64: E-17473 | T64: W_34798 | U64: JENA | V64: Mexico | X64: MSDU6387941 | AC64: 237
A65: 45877 | B65: 45881 | C65: 32 | D65: 1663-5YY0333EN | F65: 2910069933 | G65: 1197004407 | H65: 2880 | I65: C | J65: 15056C | L65: 460.51 | M65: 0.15989931 | N65: 1 | O65: 9 | P65: 57.6 | Q65: 127 | R65: CPT ALTAMIRA | S65: E-17473 | T65: W_34798 | U65: JENA | V65: Mexico | X65: MSDU6387941 | AC65: 237
A66: 45881 | B66: 45881 | C66: 33 | D66: 1663-5YY0194-MTEN/RS | F66: 2910069962 | G66: 3197002040 | H66: 2592 | I66: D | J66: 15072C | L66: 10288.26 | M66: 3.9692361 | N66: 2 | O66: 24 | P66: 189.22 | Q66: 323.9 | R66: CPT ALTAMIRA | S66: E-17540 | T66: W_34798 | U66: JENA | V66: Mexico | W66: CS000008149 | X66: avio | AC66: 238
...

Sheet SPG
A1: PFA # | B1: Item Code | C1: Item Description | D1: FG | E1: JE Zac. Customer | F1: PFA Cost | G1: Cuenta | H1: BU | P1: EUROPARTNERS
A2: CS000009338 | B2: 1663-5YY0333ENNV00 | C2: PCBA | D2: 1999-5YY1255EN | E2: JE Springfield | F2: 11000 | G2: 67180000 | H2: M19 | J2: 9338 | P2: TRINITY LOGISTICS
A3: CS000009271 | B3: 1663-5YY0196EN | C3: PCBA | D3: 1999-5YY0937EN | E3: JE Springfield | F3: 600 | G3: 67180000 | H3: M19 | P3: CH ROBINSON
A4: CS000009270 | B4: 1663-5YY0294-H01 | C4: PCBA | D4: 1905-5YY0792AN | E4: GM | F4: 23500 | G4: 67180000 | H4: M19 | P4: TRANSCONTINENTAL TDS
F5: =SUM(F2:F4) -> 35100 | P5: MEXPROUD
P6: ALLIANCESHARE
P7: FERENS
P8: ALOW
F9: 20000 | P9: DSV
F10: =F2+F3 -> 11600 | P10: SOLUTIONS CARGO
F11: =F9-F10 -> 8400 | P11: ROYALE INTERNATIONAL
P12: AERO WORLDWIDE
P13: GRAND AIR
P14: ADIONE
P15: DICEX INTERNATIONAL

Sheet Explicaciones Feb 
A1: Inbound: | K1: 178204
B2: Import Freight by Sea | F2: Premium Inbound Freight | K2: 54127.77
A3: Purchase Invoices | B3: 260255.19 | C3: Zacatecas | E3: Purchase Invoices | F3: -2314.81 | G3: Zacatecas | K3: =SUM(K1:K2) -> 232331.77
B4: 57931.99 | C4: China | F4: 79577.28 | G4: China | K4: =K3-F9 -> 16414.55
B5: 30045.75 | C5: Niss | F5: 54127.77 | G5: Niss | H5: Estos cobros de Niss se debe verificar que si es a nuestro cargo y que se le debe cobrar a SPG por el alza de la demanda de cliente.
B6: =SUM(B3:B5) -> 348232.93 | F6: =SUM(F3:F5) -> 131390.24
A7: Reversa | B7: 231546.85 | E7: Reversa | F7: 224287.24
A8: Provision | B8: 329830.83 | C8: En esta provisión se incluyen $63,220.00 de la compra de las maquinas a China de AS/Responsables Niaz y Eduardo | E8: Provision | F8: 308814.22 | H8: En esta provisión estan $65,938.00 que se le deben cobrar a ABC, pero hasta tener el cobro por parte de China.
A9: TOTAL CTA | B9: =B6-B7+B8 -> 446516.91 | C9: Se liberaron 63 contenedores. | E9: TOTAL CTA | F9: =F6-F7+F8 -> 215917.22
A11: Outbound:
B12: Freight by Land | F12: Freight by Air
A13: Purchase Invoices | B13: 145157.76 | C13: Zacatecas | E13: Purchase Invoices | F13: 18599.88 | G13: Zacatecas | H13: $17,691.32 en cobros por envios Proyectos de mas de 100 kilos porque DHL cobro por peso volumetrico.
B14: 1045.79 | C14: SPG | F14: 4180.8 | G14: China
B15: =SUM(B13:B14) -> 146203.55 | F15: =SUM(F13:F14) -> 22780.68
A16: Charge back SPG | B16: 27442 | C16: En el charge back con SPG solo se estan cobrando 7 cajas de 12 que se deben estar cobrando por mes
A17: Reversa | B17: 107774.52 | E17: Reversa | F17: 6876.39
A18: Provision | B18: 122398.2 | E18: Provision | F18: 16504.33 | H18: $7,945.22 en provisión por envios de Proyectos de mas de 100 kilos porque DHL cobrara por peso volumetrico
A19: TOTAL CTA | B19: =(B15-B16-B17+B18) -> 133385.23 | E19: TOTAL CTA | F19: =(F15-F17+F18) -> 32408.62
B21: 135000
B22: =B21-B19 -> 1614.77

Sheet Explicaciones Mar
A1: Inbound:
B2: Import Freight by Sea | F2: Premium Inbound Freight
A3: Purchase Invoices | B3: 325578.19 | C3: Zacatecas /$57,427.58 Proyectos | E3: Purchase Invoices | F3: 40835.92 | G3: Zacatecas
B4: 181768.26 | C4: China Intercompany | F4: 97508.44 | G4: China | H4: $17,670.40 de Proyectos PFA 9482
B5: 30534.83 | C5: Niss | F5: 66305.21 | G5: Niss | H5: En este mes Niss volvio a cargar en automatico al sistema sin indicar PFA ni nada $44,616.86, lo que suma de febrero a marzo $98,744.63 que debe regresar.
B6: 4301 | C6: Murten
B7: =SUM(B3:B6) -> 542182.28 | F7: =SUM(F3:F5) -> 204649.57
A8: Reversa | B8: 329830.83 | E8: Reversa | F8: 308814.22
E9: Charge back ABC | F9: 31372.8
E10: Charge back SPG | F10: 11600
